Workbook

Sheet README
A1: DCCA Salesforce Data Dictionary | C1: accenture >
A2: Hawaii DCCA Salesforce platform · objects, fields, relationships, record types, picklists and entity-relationship diagrams
A4: About this workbook
A5: Prepared | B5: 2026-10-05 (reverse-engineered from code; not yet validated with business owners)
A6: Source repository | B6: DCCA Salesforce DX project, force-app/main/default (API v67.0)
A7: Custom objects & fields | B7: Parsed from every *.object-meta.xml, *.field-meta.xml, recordTypes and globalValueSets file in source.
A8: Account, Contact, Case, Payment | B8: Not stored in source. Fields, lookups, picklists and record types taken from a read-only "sf sobject describe" of the DCCA sandbox.
A9: Code references | B9: Count of non-test Apex classes/triggers, LWC/Aura bundles and Flows that mention the object or field API name.
A10: Diagrams | B10: Generated from the relationship metadata (Mermaid ER, ELK layout) and embedded as 2× resolution images. Interactive version: analysis/10-data-model.html.
A12: Key figures (live formulas)
A13: Objects catalogued | C13: =COUNTA('Object Catalogue'!A6:A1000)
A14: Custom objects | C14: =COUNTIF('Object Catalogue'!E:E,"Custom object")
A15: Custom metadata types | C15: =COUNTIF('Object Catalogue'!E:E,"Custom metadata")
A16: Platform events | C16: =COUNTIF('Object Catalogue'!E:E,"Platform event")
A17: Fields documented | C17: =COUNTA('Field Dictionary'!A6:A20000)
A18: Relationship fields | C18: =COUNTA(Relationships!A6:A5000)
A19: Master-detail relationships | C19: =COUNTIF(Relationships!E:E,"Master-detail")
A20: Record types | C20: =COUNTA('Record Types'!A6:A5000)
A21: Picklist value rows | C21: =COUNTA('Picklist Values'!A6:A50000)
A22: Custom objects with no code references | C22: =COUNTIF('Object Catalogue'!Q:Q,"No code references")
A24: Tabs
A25: Domain Summary | B25: The 13 business domains with object, field and relationship counts, and a link to each ERD.
A26: Object Catalogue | B26: Every object: label, domain, type, description, sharing, field / record-type / relationship counts, code usage.
A27: Field Dictionary | B27: Every field: type, length, required, unique, reference target, picklist values, formula, default, description, help text.
A28: Relationships | B28: Every lookup and master-detail field with child/parent object and domain, and whether it crosses domains.
A29: Core Object References | B29: All objects that look up to Account, Contact or Case, plus the custom lookups those three objects hold.
A30: Record Types | B30: All record types per object, active flag and description.
A31: Picklist Values | B31: Every picklist value (field-specific, org-described and Global Value Sets).
A32: ERD - Overview | B32: Entity-relationship diagram: Domain overview
A33: ERD - Core Acct-Contact-Case | B33: Entity-relationship diagram: Core: Account · Contact · Case
A34: ERD - BREG Registration | B34: Entity-relationship diagram: BREG: Business Registration
A35: ERD - BREG Web Staging | B35: Entity-relationship diagram: BREG: Legacy Web Filing Staging
A36: ERD - PVL Applications | B36: Entity-relationship diagram: PVL: Applications & Portal
... A44: ERD - Service & Work Mgmt | B44: Entity-relationship diagram: Service & Work Management
A46: ERD legend
B47: Legend: solid line = master-detail (child owned by parent) · dashed line = lookup · crow's foot = "many" side · boxes with attribute rows = objects in this domain (Label, Fields, CodeRefs) · plain boxes = objects from other domains or managed packages. Lookups to User are omitted.
A49: Caveats
B50: • Configuration (profiles, sharing rules, FLS) is not covered here; see analysis/05-access-control.md.
B51: • Managed-package objects other than pymt__PaymentX__c (DocuSign dsfs__, UJET__, cterminal__) appear only as relationship targets.
B52: • "No code references" means no Apex, LWC/Aura or Flow mentions the API name. The object may still be used through page layouts, reports or integrations.

Sheet Domain Summary
A1: Domain Summary
A2: Objects grouped into business domains. All counts are live formulas over the Object Catalogue.
A3: ‹ Back to README
A5: Domain | B5: Description | C5: Objects | D5: Fields | E5: Relationship Fields (to parents) | F5: Objects with No Code References | G5: ERD Tab
A6: Core: Account · Contact · Case | B6: Shared CRM backbone used by every division. | C6: =COUNTIF('Object Catalogue'!$D:$D,A6) | D6: =SUMIF('Object Catalogue'!$D:$D,A6,'Object Catalogue'!$H:$H) | E6: =SUMIF('Object Catalogue'!$D:$D,A6,'Object Catalogue'!$K:$K) | F6: =COUNTIFS('Object Catalogue'!$D:$D,A6,'Object Catalogue'!$Q:$Q,"No code references") | G6: ERD - Core Acct-Contact-Case
A7: BREG: Business Registration | B7: Entities, filings, transactions, annuals, certificates and documents for the Business Registration Division. | C7: =COUNTIF('Object Catalogue'!$D:$D,A7) | D7: =SUMIF('Object Catalogue'!$D:$D,A7,'Object Catalogue'!$H:$H) | E7: =SUMIF('Object Catalogue'!$D:$D,A7,'Object Catalogue'!$K:$K) | F7: =COUNTIFS('Object Catalogue'!$D:$D,A7,'Object Catalogue'!$Q:$Q,"No code references") | G7: ERD - BREG Registration
A8: BREG: Legacy Web Filing Staging | B8: Staging tables that receive legacy RDPMS web filings before they are mapped onto a Case. | C8: =COUNTIF('Object Catalogue'!$D:$D,A8) | D8: =SUMIF('Object Catalogue'!$D:$D,A8,'Object Catalogue'!$H:$H) | E8: =SUMIF('Object Catalogue'!$D:$D,A8,'Object Catalogue'!$K:$K) | F8: =COUNTIFS('Object Catalogue'!$D:$D,A8,'Object Catalogue'!$Q:$Q,"No code references") | G8: ERD - BREG Web Staging
A9: PVL: Applications & Portal | B9: Professional & Vocational Licensing applications, draft/metadata-driven online forms and portal users. | C9: =COUNTIF('Object Catalogue'!$D:$D,A9) | D9: =SUMIF('Object Catalogue'!$D:$D,A9,'Object Catalogue'!$H:$H) | E9: =SUMIF('Object Catalogue'!$D:$D,A9,'Object Catalogue'!$K:$K) | F9: =COUNTIFS('Object Catalogue'!$D:$D,A9,'Object Catalogue'!$Q:$Q,"No code references") | G9: ERD - PVL Applications
A10: PVL: Licenses & License Types | B10: Issued licenses, license-type configuration, requirements, insurance/bonds and notifications. | C10: =COUNTIF('Object Catalogue'!$D:$D,A10) | D10: =SUMIF('Object Catalogue'!$D:$D,A10,'Object Catalogue'!$H:$H) | E10: =SUMIF('Object Catalogue'!$D:$D,A10,'Object Catalogue'!$K:$K) | F10: =COUNTIFS('Object Catalogue'!$D:$D,A10,'Object Catalogue'!$Q:$Q,"No code references") | G10: ERD - PVL Licenses
A11: PVL: Exams & Continuing Education | B11: Licensing exam requirements, courses, schools, instructors and earned CE / pre-licence credit. | C11: =COUNTIF('Object Catalogue'!$D:$D,A11) | D11: =SUMIF('Object Catalogue'!$D:$D,A11,'Object Catalogue'!$H:$H) | E11: =SUMIF('Object Catalogue'!$D:$D,A11,'Object Catalogue'!$K:$K) | F11: =COUNTIFS('Object Catalogue'!$D:$D,A11,'Object Catalogue'!$Q:$Q,"No code references") | G11: ERD - PVL Exams & CE
A12: Payments & Finance | B12: Transactions, line items, PaymentConnect payments, fees, deposits and reconciliation. | C12: =COUNTIF('Object Catalogue'!$D:$D,A12) | D12: =SUMIF('Object Catalogue'!$D:$D,A12,'Object Catalogue'!$H:$H) | E12: =SUMIF('Object Catalogue'!$D:$D,A12,'Object Catalogue'!$K:$K) | F12: =COUNTIFS('Object Catalogue'!$D:$D,A12,'Object Catalogue'!$Q:$Q,"No code references") | G12: ERD - Payments & Finance
A13: Securities: Filings & Exams | B13: Securities registrations (broker-dealer, investment adviser, offerings) and compliance examinations. | C13: =COUNTIF('Object Catalogue'!$D:$D,A13) | D13: =SUMIF('Object Catalogue'!$D:$D,A13,'Object Catalogue'!$H:$H) | E13: =SUMIF('Object Catalogue'!$D:$D,A13,'Object Catalogue'!$K:$K) | F13: =COUNTIFS('Object Catalogue'!$D:$D,A13,'Object Catalogue'!$Q:$Q,"No code references") | G13: ERD - Securities
A14: Enforcement: SEB & RICO | B14: Securities Enforcement Branch cases, investigations, sanctions and RICO referrals. | C14: =COUNTIF('Object Catalogue'!$D:$D,A14) | D14: =SUMIF('Object Catalogue'!$D:$D,A14,'Object Catalogue'!$H:$H) | E14: =SUMIF('Object Catalogue'!$D:$D,A14,'Object Catalogue'!$K:$K) | F14: =COUNTIFS('Object Catalogue'!$D:$D,A14,'Object Catalogue'!$Q:$Q,"No code references") | G14: ERD - Enforcement SEB-RICO
A15: CATV / INET | B15: Cable TV portal access requests and INET (Institutional Network) requests, quotes, POs and invoices. | C15: =COUNTIF('Object Catalogue'!$D:$D,A15) | D15: =SUMIF('Object Catalogue'!$D:$D,A15,'Object Catalogue'!$H:$H) | E15: =SUMIF('Object Catalogue'!$D:$D,A15,'Object Catalogue'!$K:$K) | F15: =COUNTIFS('Object Catalogue'!$D:$D,A15,'Object Catalogue'!$Q:$Q,"No code references") | G15: ERD - CATV INET
A16: Travel & Expense | B16: Staff travel approval with expense worksheets (DocuSign approval). | C16: =COUNTIF('Object Catalogue'!$D:$D,A16) | D16: =SUMIF('Object Catalogue'!$D:$D,A16,'Object Catalogue'!$H:$H) | E16: =SUMIF('Object Catalogue'!$D:$D,A16,'Object Catalogue'!$K:$K) | F16: =COUNTIFS('Object Catalogue'!$D:$D,A16,'Object Catalogue'!$Q:$Q,"No code references") | G16: ERD - Travel & Expense
A17: Service & Work Management | B17: Work items, case teams, internal IT tickets, Qualtrics logs, case auto-closer and alerts. | C17: =COUNTIF('Object Catalogue'!$D:$D,A17) | D17: =SUMIF('Object Catalogue'!$D:$D,A17,'Object Catalogue'!$H:$H) | E17: =SUMIF('Object Catalogue'!$D:$D,A17,'Object Catalogue'!$K:$K) | F17: =COUNTIFS('Object Catalogue'!$D:$D,A17,'Object Catalogue'!$Q:$Q,"No code references") | G17: ERD - Service & Work Mgmt
A18: Configuration, Logs & Metadata | B18: Custom settings, logs, custom metadata types and platform events. Not drawn as ER. | C18: =COUNTIF('Object Catalogue'!$D:$D,A18) | D18: =SUMIF('Object Catalogue'!$D:$D,A18,'Object Catalogue'!$H:$H) | E18: =SUMIF('Object Catalogue'!$D:$D,A18,'Object Catalogue'!$K:$K) | F18: =COUNTIFS('Object Catalogue'!$D:$D,A18,'Object Catalogue'!$Q:$Q,"No code references") | G18: n/a (reference only)
A19: Total | C19: =SUM(C6:C18) | D19: =SUM(D6:D18) | E19: =SUM(E6:E18) | F19: =SUM(F6:F18)
A20: "Managed package" rows (e.g. pymt__PaymentX__c) sit in Payments & Finance.

Sheet Object Catalogue
A1: Object Catalogue
A2: One row per object. Counts in columns H–K and P–Q are live formulas over the Field Dictionary, Record Types and Relationships tabs.
A3: ‹ Back to README
A5: Object API Name | B5: Label | C5: Plural Label | D5: Domain | E5: Object Type | F5: Description | G5: Sharing Model | H5: Total Fields | I5: Custom Fields | J5: Record Types | K5: Relationship Fields (to parents) | L5: Apex Files | M5: LWC / Aura Bundles | N5: Flows | O5: Total Code References | P5: Referenced By (child lookups) | Q5: Code Usage Flag | R5: ERD Tab
A6: Account | B6: Account | C6: Accounts | D6: Core: Account · Contact · Case | E6: Standard | F6: Described from DCCA sandbox (not in source) | H6: =COUNTIF('Field Dictionary'!$A:$A,A6) | I6: =COUNTIFS('Field Dictionary'!$A:$A,A6,'Field Dictionary'!$T:$T,"Custom") | J6: =COUNTIF('Record Types'!$A:$A,A6) | K6: =COUNTIF(Relationships!$A:$A,A6) | L6: 144 | M6: 68 | N6: 42 | O6: =SUM(L6:N6) | P6: =COUNTIF(Relationships!$F:$F,A6) | Q6: =IF(AND(O6=0,E6="Custom object"),"No code references","") | R6: ERD - Core Acct-Contact-Case
A7: Case | B7: Case | C7: Cases | D7: Core: Account · Contact · Case | E7: Standard | F7: Described from DCCA sandbox (not in source) | H7: =COUNTIF('Field Dictionary'!$A:$A,A7) | I7: =COUNTIFS('Field Dictionary'!$A:$A,A7,'Field Dictionary'!$T:$T,"Custom") | J7: =COUNTIF('Record Types'!$A:$A,A7) | K7: =COUNTIF(Relationships!$A:$A,A7) | L7: 170 | M7: 71 | N7: 102 | O7: =SUM(L7:N7) | P7: =COUNTIF(Relationships!$F:$F,A7) | Q7: =IF(AND(O7=0,E7="Custom object"),"No code references","") | R7: ERD - Core Acct-Contact-Case
A8: Contact | B8: Contact | C8: Contacts | D8: Core: Account · Contact · Case | E8: Standard | F8: Described from DCCA sandbox (not in source) | H8: =COUNTIF('Field Dictionary'!$A:$A,A8) | I8: =COUNTIFS('Field Dictionary'!$A:$A,A8,'Field Dictionary'!$T:$T,"Custom") | J8: =COUNTIF('Record Types'!$A:$A,A8) | K8: =COUNTIF(Relationships!$A:$A,A8) | L8: 50 | M8: 24 | N8: 19 | O8: =SUM(L8:N8) | P8: =COUNTIF(Relationships!$F:$F,A8) | Q8: =IF(AND(O8=0,E8="Custom object"),"No code references","") | R8: ERD - Core Acct-Contact-Case
A9: BREG_ADDRESS_PROTECTION__c | B9: ADDRESS PROTECTION | C9: ADDRESS PROTECTIONs | D9: BREG: Business Registration | E9: Custom object | G9: ReadWrite | H9: =COUNTIF('Field Dictionary'!$A:$A,A9) | I9: =COUNTIFS('Field Dictionary'!$A:$A,A9,'Field Dictionary'!$T:$T,"Custom") | J9: =COUNTIF('Record Types'!$A:$A,A9) | K9: =COUNTIF(Relationships!$A:$A,A9) | L9: 1 | M9: 0 | N9: 0 | O9: =SUM(L9:N9) | P9: =COUNTIF(Relationships!$F:$F,A9) | Q9: =IF(AND(O9=0,E9="Custom object"),"No code references","") | R9: ERD - BREG Registration
A10: BREG_File_Number_Sequence__c | B10: BREG File Number Sequence | D10: BREG: Business Registration | E10: Custom object | H10: =COUNTIF('Field Dictionary'!$A:$A,A10) | I10: =COUNTIFS('Field Dictionary'!$A:$A,A10,'Field Dictionary'!$T:$T,"Custom") | J10: =COUNTIF('Record Types'!$A:$A,A10) | K10: =COUNTIF(Relationships!$A:$A,A10) | L10: 1 | M10: 0 | N10: 0 | O10: =SUM(L10:N10) | P10: =COUNTIF(Relationships!$F:$F,A10) | Q10: =IF(AND(O10=0,E10="Custom object"),"No code references","") | R10: ERD - BREG Registration
A11: breg_Account_Affiliation__c | B11: Account Affiliation | C11: Account Affiliations | D11: BREG: Business Registration | E11: Custom object | F11: Aalta BREG-59 | G11: ReadWrite | H11: =COUNTIF('Field Dictionary'!$A:$A,A11) | I11: =COUNTIFS('Field Dictionary'!$A:$A,A11,'Field Dictionary'!$T:$T,"Custom") | J11: =COUNTIF('Record Types'!$A:$A,A11) | K11: =COUNTIF(Relationships!$A:$A,A11) | L11: 43 | M11: 7 | N11: 5 | O11: =SUM(L11:N11) | P11: =COUNTIF(Relationships!$F:$F,A11) | Q11: =IF(AND(O11=0,E11="Custom object"),"No code references","") | R11: ERD - BREG Registration
A12: breg_Acquisition_Transaction__c | B12: Acquisition Transaction | C12: Acquisition Transactions | D12: BREG: Business Registration | E12: Custom object | F12: Aalta BREG-2653 | G12: ReadWrite | H12: =COUNTIF('Field Dictionary'!$A:$A,A12) | I12: =COUNTIFS('Field Dictionary'!$A:$A,A12,'Field Dictionary'!$T:$T,"Custom") | J12: =COUNTIF('Record Types'!$A:$A,A12) | K12: =COUNTIF(Relationships!$A:$A,A12) | L12: 0 | M12: 0 | N12: 0 | O12: =SUM(L12:N12) | P12: =COUNTIF(Relationships!$F:$F,A12) | Q12: =IF(AND(O12=0,E12="Custom object"),"No code references","") | R12: ERD - BREG Registration
A13: breg_Agent_Search_List__c | B13: Agent Search List | C13: Agent Search Lists | D13: BREG: Business Registration | E13: Custom object | G13: ReadWrite | H13: =COUNTIF('Field Dictionary'!$A:$A,A13) | I13: =COUNTIFS('Field Dictionary'!$A:$A,A13,'Field Dictionary'!$T:$T,"Custom") | J13: =COUNTIF('Record Types'!$A:$A,A13) | K13: =COUNTIF(Relationships!$A:$A,A13) | L13: 4 | M13: 0 | N13: 1 | O13: =SUM(L13:N13) | P13: =COUNTIF(Relationships!$F:$F,A13) | Q13: =IF(AND(O13=0,E13="Custom object"),"No code references","") | R13: ERD - BREG Registration
A14: breg_Agent_Search_Result__c | B14: Agent Search Result | C14: Agent Search Results | D14: BREG: Business Registration | E14: Custom object | G14: ControlledByParent | H14: =COUNTIF('Field Dictionary'!$A:$A,A14) | I14: =COUNTIFS('Field Dictionary'!$A:$A,A14,'Field Dictionary'!$T:$T,"Custom") | J14: =COUNTIF('Record Types'!$A:$A,A14) | K14: =COUNTIF(Relationships!$A:$A,A14) | L14: 1 | M14: 0 | N14: 0 | O14: =SUM(L14:N14) | P14: =COUNTIF(Relationships!$F:$F,A14) | Q14: =IF(AND(O14=0,E14="Custom object"),"No code references","") | R14: ERD - BREG Registration
A15: breg_Annual__c | B15: Annual | C15: Annuals | D15: BREG: Business Registration | E15: Custom object | F15: Aalta BREG-60 | G15: ReadWrite | H15: =COUNTIF('Field Dictionary'!$A:$A,A15) | I15: =COUNTIFS('Field Dictionary'!$A:$A,A15,'Field Dictionary'!$T:$T,"Custom") | J15: =COUNTIF('Record Types'!$A:$A,A15) | K15: =COUNTIF(Relationships!$A:$A,A15) | L15: 24 | M15: 4 | N15: 8 | O15: =SUM(L15:N15) | P15: =COUNTIF(Relationships!$F:$F,A15) | Q15: =IF(AND(O15=0,E15="Custom object"),"No code references","") | R15: ERD - BREG Registration
A16: breg_BRIM_Transaction_Event__b | B16: Transaction Event | C16: Transaction Events | D16: BREG: Business Registration | E16: Big object | H16: =COUNTIF('Field Dictionary'!$A:$A,A16) | I16: =COUNTIFS('Field Dictionary'!$A:$A,A16,'Field Dictionary'!$T:$T,"Custom") | J16: =COUNTIF('Record Types'!$A:$A,A16) | K16: =COUNTIF(Relationships!$A:$A,A16) | L16: 0 | M16: 0 | N16: 0 | O16: =SUM(L16:N16) | P16: =COUNTIF(Relationships!$F:$F,A16) | Q16: =IF(AND(O16=0,E16="Custom object"),"No code references","") | R16: ERD - BREG Registration
A17: breg_Batch_Job_Execution__c | B17: Batch Job Execution | C17: Batch Job Executions | D17: BREG: Business Registration | E17: Custom object | F17: Universal object for storing batch job execution results and logs | G17: ReadWrite | H17: =COUNTIF('Field Dictionary'!$A:$A,A17) | I17: =COUNTIFS('Field Dictionary'!$A:$A,A17,'Field Dictionary'!$T:$T,"Custom") | J17: =COUNTIF('Record Types'!$A:$A,A17) | K17: =COUNTIF(Relationships!$A:$A,A17) | L17: 8 | M17: 0 | N17: 0 | O17: =SUM(L17:N17) | P17: =COUNTIF(Relationships!$F:$F,A17) | Q17: =IF(AND(O17=0,E17="Custom object"),"No code references","") | R17: ERD - BREG Registration
A18: breg_Case_Staging__c | B18: Case Staging | C18: Case Staging | D18: BREG: Business Registration | E18: Custom object | G18: ReadWrite | H18: =COUNTIF('Field Dictionary'!$A:$A,A18) | I18: =COUNTIFS('Field Dictionary'!$A:$A,A18,'Field Dictionary'!$T:$T,"Custom") | J18: =COUNTIF('Record Types'!$A:$A,A18) | K18: =COUNTIF(Relationships!$A:$A,A18) | L18: 3 | M18: 0 | N18: 0 | O18: =SUM(L18:N18) | P18: =COUNTIF(Relationships!$F:$F,A18) | Q18: =IF(AND(O18=0,E18="Custom object"),"No code references","") | R18: ERD - BREG Registration
A19: breg_Certificate__c | B19: Certificate | C19: Certificates | D19: BREG: Business Registration | E19: Custom object | G19: ReadWrite | H19: =COUNTIF('Field Dictionary'!$A:$A,A19) | I19: =COUNTIFS('Field Dictionary'!$A:$A,A19,'Field Dictionary'!$T:$T,"Custom") | J19: =COUNTIF('Record Types'!$A:$A,A19) | K19: =COUNTIF(Relationships!$A:$A,A19) | L19: 7 | M19: 0 | N19: 1 | O19: =SUM(L19:N19) | P19: =COUNTIF(Relationships!$F:$F,A19) | Q19: =IF(AND(O19=0,E19="Custom object"),"No code references","") | R19: ERD - BREG Registration
A20: breg_DBEDT_Report__c | B20: DBEDT Report | C20: DBEDT Reports | D20: BREG: Business Registration | E20: Custom object | G20: ReadWrite | H20: =COUNTIF('Field Dictionary'!$A:$A,A20) | I20: =COUNTIFS('Field Dictionary'!$A:$A,A20,'Field Dictionary'!$T:$T,"Custom") | J20: =COUNTIF('Record Types'!$A:$A,A20) | K20: =COUNTIF(Relationships!$A:$A,A20) | L20: 1 | M20: 0 | N20: 0 | O20: =SUM(L20:N20) | P20: =COUNTIF(Relationships!$F:$F,A20) | Q20: =IF(AND(O20=0,E20="Custom object"),"No code references","") | R20: ERD - BREG Registration
A21: breg_Document__c | B21: Document | C21: Documents | D21: BREG: Business Registration | E21: Custom object | G21: ReadWrite | H21: =COUNTIF('Field Dictionary'!$A:$A,A21) | I21: =COUNTIFS('Field Dictionary'!$A:$A,A21,'Field Dictionary'!$T:$T,"Custom") | J21: =COUNTIF('Record Types'!$A:$A,A21) | K21: =COUNTIF(Relationships!$A:$A,A21) | L21: 25 | M21: 1 | N21: 4 | O21: =SUM(L21:N21) | P21: =COUNTIF(Relationships!$F:$F,A21) | Q21: =IF(AND(O21=0,E21="Custom object"),"No code references","") | R21: ERD - BREG Registration
A22: breg_Email_Log__c | B22: Email Log | C22: Email Logs | D22: BREG: Business Registration | E22: Custom object | G22: ReadWrite | H22: =COUNTIF('Field Dictionary'!$A:$A,A22) | I22: =COUNTIFS('Field Dictionary'!$A:$A,A22,'Field Dictionary'!$T:$T,"Custom") | J22: =COUNTIF('Record Types'!$A:$A,A22) | K22: =COUNTIF(Relationships!$A:$A,A22) | L22: 1 | M22: 0 | N22: 1 | O22: =SUM(L22:N22) | P22: =COUNTIF(Relationships!$F:$F,A22) | Q22: =IF(AND(O22=0,E22="Custom object"),"No code references","") | R22: ERD - BREG Registration
A23: breg_Entity_List_Item__c | B23: Entity List Item | C23: Entity List Items | D23: BREG: Business Registration | E23: Custom object | F23: Aalta BREG-58 | G23: ControlledByParent | H23: =COUNTIF('Field Dictionary'!$A:$A,A23) | I23: =COUNTIFS('Field Dictionary'!$A:$A,A23,'Field Dictionary'!$T:$T,"Custom") | J23: =COUNTIF('Record Types'!$A:$A,A23) | K23: =COUNTIF(Relationships!$A:$A,A23) | L23: 0 | M23: 0 | N23: 0 | O23: =SUM(L23:N23) | P23: =COUNTIF(Relationships!$F:$F,A23) | Q23: =IF(AND(O23=0,E23="Custom object"),"No code references","") | R23: ERD - BREG Registration
A24: breg_Entity_List_Result__c | B24: Entity List Result | C24: Entity List Results | D24: BREG: Business Registration | E24: Custom object | F24: Aalta BREG-58 | G24: ControlledByParent | H24: =COUNTIF('Field Dictionary'!$A:$A,A24) | I24: =COUNTIFS('Field Dictionary'!$A:$A,A24,'Field Dictionary'!$T:$T,"Custom") | J24: =COUNTIF('Record Types'!$A:$A,A24) | K24: =COUNTIF(Relationships!$A:$A,A24) | L24: 5 | M24: 0 | N24: 0 | O24: =SUM(L24:N24) | P24: =COUNTIF(Relationships!$F:$F,A24) | Q24: =IF(AND(O24=0,E24="Custom object"),"No code references","") | R24: ERD - BREG Registration
A25: breg_Entity_List__c | B25: Entity List | C25: Entity Lists | D25: BREG: Business Registration | E25: Custom object | F25: Aalta BREG-58 | G25: ReadWrite | H25: =COUNTIF('Field Dictionary'!$A:$A,A25) | I25: =COUNTIFS('Field Dictionary'!$A:$A,A25,'Field Dictionary'!$T:$T,"Custom") | J25: =COUNTIF('Record Types'!$A:$A,A25) | K25: =COUNTIF(Relationships!$A:$A,A25) | L25: 5 | M25: 0 | N25: 1 | O25: =SUM(L25:N25) | P25: =COUNTIF(Relationships!$F:$F,A25) | Q25: =IF(AND(O25=0,E25="Custom object"),"No code references","") | R25: ERD - BREG Registration
A26: breg_Fee__c | B26: Fee | C26: Fees | D26: BREG: Business Registration | E26: Custom object | F26: Aalta BREG-933 | G26: ReadWrite | H26: =COUNTIF('Field Dictionary'!$A:$A,A26) | I26: =COUNTIFS('Field Dictionary'!$A:$A,A26,'Field Dictionary'!$T:$T,"Custom") | J26: =COUNTIF('Record Types'!$A:$A,A26) | K26: =COUNTIF(Relationships!$A:$A,A26) | L26: 8 | M26: 0 | N26: 0 | O26: =SUM(L26:N26) | P26: =COUNTIF(Relationships!$F:$F,A26) | Q26: =IF(AND(O26=0,E26="Custom object"),"No code references","") | R26: ERD - BREG Registration
A27: breg_Form_Configuration_Item__c | B27: Form Configuration Item | C27: Form Configuration Items | D27: BREG: Business Registration | E27: Custom object | G27: ControlledByParent | H27: =COUNTIF('Field Dictionary'!$A:$A,A27) | I27: =COUNTIFS('Field Dictionary'!$A:$A,A27,'Field Dictionary'!$T:$T,"Custom") | J27: =COUNTIF('Record Types'!$A:$A,A27) | K27: =COUNTIF(Relationships!$A:$A,A27) | L27: 4 | M27: 1 | N27: 0 | O27: =SUM(L27:N27) | P27: =COUNTIF(Relationships!$F:$F,A27) | Q27: =IF(AND(O27=0,E27="Custom object"),"No code references","") | R27: ERD - BREG Registration
A28: breg_Form_Configuration__c | B28: Form Configuration | C28: Form Configurations | D28: BREG: Business Registration | E28: Custom object | G28: ReadWrite | H28: =COUNTIF('Field Dictionary'!$A:$A,A28) | I28: =COUNTIFS('Field Dictionary'!$A:$A,A28,'Field Dictionary'!$T:$T,"Custom") | J28: =COUNTIF('Record Types'!$A:$A,A28) | K28: =COUNTIF(Relationships!$A:$A,A28) | L28: 16 | M28: 4 | N28: 7 | O28: =SUM(L28:N28) | P28: =COUNTIF(Relationships!$F:$F,A28) | Q28: =IF(AND(O28=0,E28="Custom object"),"No code references","") | R28: ERD - BREG Registration
A29: breg_Log__c | B29: Log | C29: Logs | D29: BREG: Business Registration | E29: Custom object | F29: Aalta BREGMO-57 | G29: ReadWrite | H29: =COUNTIF('Field Dictionary'!$A:$A,A29) | I29: =COUNTIFS('Field Dictionary'!$A:$A,A29,'Field Dictionary'!$T:$T,"Custom") | J29: =COUNTIF('Record Types'!$A:$A,A29) | K29: =COUNTIF(Relationships!$A:$A,A29) | L29: 2 | M29: 0 | N29: 1 | O29: =SUM(L29:N29) | P29: =COUNTIF(Relationships!$F:$F,A29) | Q29: =IF(AND(O29=0,E29="Custom object"),"No code references","") | R29: ERD - BREG Registration
A30: breg_Notification__c | B30: Notification | C30: Notifications | D30: BREG: Business Registration | E30: Custom object | F30: Allta BREG-972 | G30: ReadWrite | H30: =COUNTIF('Field Dictionary'!$A:$A,A30) | I30: =COUNTIFS('Field Dictionary'!$A:$A,A30,'Field Dictionary'!$T:$T,"Custom") | J30: =COUNTIF('Record Types'!$A:$A,A30) | K30: =COUNTIF(Relationships!$A:$A,A30) | L30: 2 | M30: 0 | N30: 5 | O30: =SUM(L30:N30) | P30: =COUNTIF(Relationships!$F:$F,A30) | Q30: =IF(AND(O30=0,E30="Custom object"),"No code references","") | R30: ERD - BREG Registration
A31: breg_RDPMS_Adhoc_Request__c | B31: RDPMS Adhoc Request | C31: RDPMS Adhoc Requests | D31: BREG: Business Registration | E31: Custom object | G31: ReadWrite | H31: =COUNTIF('Field Dictionary'!$A:$A,A31) | I31: =COUNTIFS('Field Dictionary'!$A:$A,A31,'Field Dictionary'!$T:$T,"Custom") | J31: =COUNTIF('Record Types'!$A:$A,A31) | K31: =COUNTIF(Relationships!$A:$A,A31) | L31: 1 | M31: 0 | N31: 2 | O31: =SUM(L31:N31) | P31: =COUNTIF(Relationships!$F:$F,A31) | Q31: =IF(AND(O31=0,E31="Custom object"),"No code references","") | R31: ERD - BREG Registration
A32: breg_Rejection_Reason__c | B32: Rejection Reason | C32: Rejection Reasons | D32: BREG: Business Registration | E32: Custom object | G32: ReadWrite | H32: =COUNTIF('Field Dictionary'!$A:$A,A32) | I32: =COUNTIFS('Field Dictionary'!$A:$A,A32,'Field Dictionary'!$T:$T,"Custom") | J32: =COUNTIF('Record Types'!$A:$A,A32) | K32: =COUNTIF(Relationships!$A:$A,A32) | L32: 0 | M32: 0 | N32: 1 | O32: =SUM(L32:N32) | P32: =COUNTIF(Relationships!$F:$F,A32) | Q32: =IF(AND(O32=0,E32="Custom object"),"No code references","") | R32: ERD - BREG Registration
A33: breg_Search_Log__c | B33: BREG Search Log | C33: BREG Search Logs | D33: BREG: Business Registration | E33: Custom object | F33: Stores search log entries for BREG Name Clearance searches including search terms, filters, and request details | G33: ReadWrite | H33: =COUNTIF('Field Dictionary'!$A:$A,A33) | I33: =COUNTIFS('Field Dictionary'!$A:$A,A33,'Field Dictionary'!$T:$T,"Custom") | J33: =COUNTIF('Record Types'!$A:$A,A33) | K33: =COUNTIF(Relationships!$A:$A,A33) | L33: 3 | M33: 0 | N33: 0 | O33: =SUM(L33:N33) | P33: =COUNTIF(Relationships!$F:$F,A33) | Q33: =IF(AND(O33=0,E33="Custom object"),"No code references","") | R33: ERD - BREG Registration
A34: breg_Stock__c | B34: Stock | C34: Stocks | D34: BREG: Business Registration | E34: Custom object | F34: Aalta BREG-64 | G34: ReadWrite | H34: =COUNTIF('Field Dictionary'!$A:$A,A34) | I34: =COUNTIFS('Field Dictionary'!$A:$A,A34,'Field Dictionary'!$T:$T,"Custom") | J34: =COUNTIF('Record Types'!$A:$A,A34) | K34: =COUNTIF(Relationships!$A:$A,A34) | L34: 15 | M34: 5 | N34: 0 | O34: =SUM(L34:N34) | P34: =COUNTIF(Relationships!$F:$F,A34) | Q34: =IF(AND(O34=0,E34="Custom object"),"No code references","") | R34: ERD - BREG Registration
A35: breg_TN_TM_SM__c | B35: TN/TM/SM | C35: TN/TM/SM | D35: BREG: Business Registration | E35: Custom object | G35: ReadWrite | H35: =COUNTIF('Field Dictionary'!$A:$A,A35) | I35: =COUNTIFS('Field Dictionary'!$A:$A,A35,'Field Dictionary'!$T:$T,"Custom") | J35: =COUNTIF('Record Types'!$A:$A,A35) | K35: =COUNTIF(Relationships!$A:$A,A35) | L35: 34 | M35: 5 | N35: 10 | O35: =SUM(L35:N35) | P35: =COUNTIF(Relationships!$F:$F,A35) | Q35: =IF(AND(O35=0,E35="Custom object"),"No code references","") | R35: ERD - BREG Registration
A36: breg_Test_Annual__c | B36: Test Annual | C36: Test Annuals | D36: BREG: Business Registration | E36: Custom object | F36: Aalta BREG-60 | G36: ReadWrite | H36: =COUNTIF('Field Dictionary'!$A:$A,A36) | I36: =COUNTIFS('Field Dictionary'!$A:$A,A36,'Field Dictionary'!$T:$T,"Custom") | J36: =COUNTIF('Record Types'!$A:$A,A36) | K36: =COUNTIF(Relationships!$A:$A,A36) | L36: 1 | M36: 0 | N36: 0 | O36: =SUM(L36:N36) | P36: =COUNTIF(Relationships!$F:$F,A36) | Q36: =IF(AND(O36=0,E36="Custom object"),"No code references","") | R36: ERD - BREG Registration
A37: breg_Transaction_Address__c | B37: BREG Transaction Address | C37: BREG Transaction Addresses | D37: BREG: Business Registration | E37: Custom object | G37: ControlledByParent | H37: =COUNTIF('Field Dictionary'!$A:$A,A37) | I37: =COUNTIFS('Field Dictionary'!$A:$A,A37,'Field Dictionary'!$T:$T,"Custom") | J37: =COUNTIF('Record Types'!$A:$A,A37) | K37: =COUNTIF(Relationships!$A:$A,A37) | L37: 5 | M37: 0 | N37: 0 | O37: =SUM(L37:N37) | P37: =COUNTIF(Relationships!$F:$F,A37) | Q37: =IF(AND(O37=0,E37="Custom object"),"No code references","") | R37: ERD - BREG Registration
A38: breg_Transaction_Business_Info__c | B38: Transaction Business Info | C38: Transaction Business Info | D38: BREG: Business Registration | E38: Custom object | F38: Aalta BREG-2269 | G38: ReadWrite | H38: =COUNTIF('Field Dictionary'!$A:$A,A38) | I38: =COUNTIFS('Field Dictionary'!$A:$A,A38,'Field Dictionary'!$T:$T,"Custom") | J38: =COUNTIF('Record Types'!$A:$A,A38) | K38: =COUNTIF(Relationships!$A:$A,A38) | L38: 5 | M38: 0 | N38: 0 | O38: =SUM(L38:N38) | P38: =COUNTIF(Relationships!$F:$F,A38) | Q38: =IF(AND(O38=0,E38="Custom object"),"No code references","") | R38: ERD - BREG Registration
A39: breg_Transaction__c | B39: BREG Transaction | C39: BREG Transactions | D39: BREG: Business Registration | E39: Custom object | F39: Aalta BREG-62 | G39: ReadWrite | H39: =COUNTIF('Field Dictionary'!$A:$A,A39) | I39: =COUNTIFS('Field Dictionary'!$A:$A,A39,'Field Dictionary'!$T:$T,"Custom") | J39: =COUNTIF('Record Types'!$A:$A,A39) | K39: =COUNTIF(Relationships!$A:$A,A39) | L39: 28 | M39: 0 | N39: 5 | O39: =SUM(L39:N39) | P39: =COUNTIF(Relationships!$F:$F,A39) | Q39: =IF(AND(O39=0,E39="Custom object"),"No code references","") | R39: ERD - BREG Registration
A40: breg_WEB_WEB_ADDRESSES__c | B40: WEB ADDRESSES | C40: WEB ADDRESSESs | D40: BREG: Legacy Web Filing Staging | E40: Custom object | G40: ReadWrite | H40: =COUNTIF('Field Dictionary'!$A:$A,A40) | I40: =COUNTIFS('Field Dictionary'!$A:$A,A40,'Field Dictionary'!$T:$T,"Custom") | J40: =COUNTIF('Record Types'!$A:$A,A40) | K40: =COUNTIF(Relationships!$A:$A,A40) | L40: 2 | M40: 0 | N40: 0 | O40: =SUM(L40:N40) | P40: =COUNTIF(Relationships!$F:$F,A40) | Q40: =IF(AND(O40=0,E40="Custom object"),"No code references","") | R40: ERD - BREG Web Staging
A41: breg_WEB_WEB_BUSINESS_INFO__c | B41: WEB BUSINESS INFO | C41: WEB BUSINESS INFOs | D41: BREG: Legacy Web Filing Staging | E41: Custom object | G41: ReadWrite | H41: =COUNTIF('Field Dictionary'!$A:$A,A41) | I41: =COUNTIFS('Field Dictionary'!$A:$A,A41,'Field Dictionary'!$T:$T,"Custom") | J41: =COUNTIF('Record Types'!$A:$A,A41) | K41: =COUNTIF(Relationships!$A:$A,A41) | L41: 1 | M41: 0 | N41: 0 | O41: =SUM(L41:N41) | P41: =COUNTIF(Relationships!$F:$F,A41) | Q41: =IF(AND(O41=0,E41="Custom object"),"No code references","") | R41: ERD - BREG Web Staging
...

Sheet Field Dictionary
A1: Field Dictionary
A2: 6,673 fields. Custom objects from source metadata; Account, Contact, Case and pymt__PaymentX__c from a read-only describe of the DCCA sandbox (all standard + custom fields).
A3: ‹ Back to README
A5: Object API Name | B5: Object Label | C5: Domain | D5: Field API Name | E5: Field Label | F5: Data Type | G5: Length / Precision | H5: Required | I5: Unique | J5: External ID | K5: Reference To | L5: Relationship Name | M5: Relationship Type | N5: Picklist Values / Value Set | O5: Formula / Roll-up | P5: Default Value | Q5: Description | R5: Help Text | S5: History Tracked | T5: Standard / Custom | U5: Files Referencing Field | V5: Source
A6: Account | B6: Account | C6: Core: Account · Contact · Case | D6: AccountNumber | E6: Account Number | F6: Text | G6: 40 | T6: Standard | V6: Org describe (DCCA sandbox)
A7: Account | B7: Account | C7: Core: Account · Contact · Case | D7: AccountSource | E7: Account Source | F7: Picklist | G7: 255 | N7: Advertisement; Customer Event; Employee Referral; Google AdWords; Other; Partner; Purchased List; Trade Show; Webinar; Website | T7: Standard | V7: Org describe (DCCA sandbox)
A8: Account | B8: Account | C8: Core: Account · Contact · Case | D8: AnnualRevenue | E8: Annual Revenue | F8: Currency | G8: 18,0 | T8: Standard | V8: Org describe (DCCA sandbox)
A9: Account | B9: Account | C9: Core: Account · Contact · Case | D9: BillingAddress | E9: Billing Address | F9: Address | T9: Standard | V9: Org describe (DCCA sandbox)
A10: Account | B10: Account | C10: Core: Account · Contact · Case | D10: BillingCity | E10: Billing City | F10: Text | G10: 40 | T10: Standard | V10: Org describe (DCCA sandbox)
A11: Account | B11: Account | C11: Core: Account · Contact · Case | D11: BillingCountry | E11: Billing Country | F11: Text | G11: 80 | T11: Standard | V11: Org describe (DCCA sandbox)
A12: Account | B12: Account | C12: Core: Account · Contact · Case | D12: BillingCountryCode | E12: Billing Country Code | F12: Picklist | G12: 10 | N12: AF; AX; AL; DZ; AS; AD; AO; AI; AQ; AG; AR; AM; AW; AU; AT; AZ; BS; BH; BD; BB; BY; BE; BZ; BJ; BM; BT; BO; BQ; BA; BW; BV; BR; IO; BN; BG; BF; BI; KH; CM; CA; CV; KY; CF; TD; CE; CL; CN; TW; CX; CC; CO; KM; CG; CD; CK; CR; CI; HR; CU; CP; CW; CY; CZ; DK; DJ; DM; DO; TP; EC; EG; SV; GQ; ER; EE; ET; FK; FO; FJ; FI; FR; GF; PF; TF; GA; GM; GE; DE; GH; GI; GR; GL; GD; GP; GU; GT; GG; GN; GW; GY; HT; HM; VA; HN; HK; HU; IS; IN; ID; IR; IQ; IE; IG; IM; IL; IT; JR; JM; JP; JE; JO; KZ; KE; KI; KP; KR; KW; KG; LA; LV; LB; LS; LR; LY; LI; LT; LU; MO; MK; MG; MW; MY; MV; ML; MT; MH; MQ; MR; MU; YT; MX; FM; MD; MC; MN; ME; MS; MA; MZ; MM; NA; NR; NP; NL; AN; NC; NZ; NI; NE; NG; NU; NF; NO; OM; PK; PS; PA; PG; PY; PE; PH; PN; PL; PT; PR; QA; RE; RO; RU; RW; BL; SH; KN; LC; MF; PM; VC; WS; SM; ST; SA; SN; RS; SC; SL; SG; SX; SK; SI; SB; SO; ZA; GS; SS; ES; LK; SD; SR; SJ; SZ; SE; CH; SY; TJ; TZ; TH; TL; TG; TK; TO; TT; TN; TR; TM; TC; TV; UG; UA; AE; GB; US; UM; UY; UZ; VU; VE; VN; VG; VI; WF; EH; YE; YU; ZM; ZW | P12: US | T12: Standard | V12: Org describe (DCCA sandbox)
A13: Account | B13: Account | C13: Core: Account · Contact · Case | D13: BillingGeocodeAccuracy | E13: Billing Geocode Accuracy | F13: Picklist | G13: 40 | N13: Address; NearAddress; Block; Street; ExtendedZip; Zip; Neighborhood; City; County; State; Unknown | T13: Standard | V13: Org describe (DCCA sandbox)
A14: Account | B14: Account | C14: Core: Account · Contact · Case | D14: BillingLatitude | E14: Billing Latitude | F14: Number | G14: 18,15 | T14: Standard | V14: Org describe (DCCA sandbox)
A15: Account | B15: Account | C15: Core: Account · Contact · Case | D15: BillingLongitude | E15: Billing Longitude | F15: Number | G15: 18,15 | T15: Standard | V15: Org describe (DCCA sandbox)
A16: Account | B16: Account | C16: Core: Account · Contact · Case | D16: BillingPostalCode | E16: Billing Zip/Postal Code | F16: Text | G16: 20 | T16: Standard | V16: Org describe (DCCA sandbox)
A17: Account | B17: Account | C17: Core: Account · Contact · Case | D17: BillingState | E17: Billing State/Province | F17: Text | G17: 80 | T17: Standard | V17: Org describe (DCCA sandbox)
A18: Account | B18: Account | C18: Core: Account · Contact · Case | D18: BillingStateCode | E18: Billing State/Province Code | F18: Picklist | G18: 10 | N18: AC; AG; AG; AL; AL; AK; AB; AL; AP; AM; AS; AN; AN; AP; 34; AO; AR; AZ; AR; AA; AE; AP; AR; AP; AS; AT; ACT; AV; BA; BC; BS; BA; BT; 11; BL; BN; BG; BI; BR; BO; BZ; BS; BR; BC; CA; CA; CL; CM; CB; CI; CW; CE; CT; CZ; CN; CE; CH; CT; CS; CH; CH; 71; 50; CE; CO; CL; CO; CO; CT; CO; CS; CR; KR; CN; DN; DD; DE; DL; DC; DF; DL; D; DG; EN; ES; DF; FM; FM; FE; FI; FL; FG; FC; FR; 35; G; 62; GE; GA; GA; GO; GO; GR; GU; GT; 44; 45; GR; 52; GJ; 46; HR; HI; 13; 23; 41; HG; HP; 91; 42; 43; ID; IL; IM; IN; IA; IS; JA; JK; JH; 32; 36; 22; KS; KA; KY; KL; KY; KE; KK; AQ; LD; LS; SP; LT; LE; LC; LM; 21; LK; LI; LO; LD; LA; LH; LU; 92; MC; MP; MH; ME; MN; MB; MN; MA; MH; MD; MS; MA; MT; MT; MS; MO; MH; VS; ML; ME; ME; MI; MI; MI; MG; MN; MS; MO; MZ; MO; MN; MT; MB; MO; NL; NA; NA; NE; 15; NV; NB; NL; NH; NJ; NM; NSW; NY; 64; NC; ND; MP; NT; NT; NO; NS; NL; NU; NU; OA; OR; OY; OG; OH; OK; OT; ON; OR; OR; PD; PW; PA; PA; PB; PR; PR; PV; PA; PE; PG; PU; PE; PC; PI; PI; PT; PN; PZ; PO; PE; PY; PB; PR; PB; 63; QC; QLD; QE; QR; RG; RJ; RA; RC; RE; RI; RI; RN; RJ; RN; RS; RM; RO; RR; RN; RO; SA; SL; SC; SP; SK; SS; SV; SE; 61; 37; 31; 14; 51; SI; SK; SI; SO; SO; SO; SA; SC; SD; SR; TB; TM; TN; TA; TAS; TN; TE; TR; TX; 12; TA; TL; TO; TP; TN; TV; TS; TR; TO; UD; UM; VI; UT; UT; UP; VA; VE; VE; VB; VC; VT; VR; VV; VI; VIC; VA; VT; WA; WD; WB; WA; WH; WV; WX; WW; WI; WY; 65; 54; YU; YT; 53; ZA; 33 | T18: Standard | V18: Org describe (DCCA sandbox)
A19: Account | B19: Account | C19: Core: Account · Contact · Case | D19: BillingStreet | E19: Billing Street | F19: TextArea | G19: 255 | T19: Standard | V19: Org describe (DCCA sandbox)
A20: Account | B20: Account | C20: Core: Account · Contact · Case | D20: CreatedById | E20: Created By ID | F20: Lookup | G20: 18 | K20: User | L20: CreatedBy | M20: Lookup | T20: Standard | V20: Org describe (DCCA sandbox)
A21: Account | B21: Account | C21: Core: Account · Contact · Case | D21: CreatedDate | E21: Created Date | F21: DateTime | T21: Standard | V21: Org describe (DCCA sandbox)
A22: Account | B22: Account | C22: Core: Account · Contact · Case | D22: Description | E22: Account Description | F22: TextArea | G22: 32000 | T22: Standard | V22: Org describe (DCCA sandbox)
A23: Account | B23: Account | C23: Core: Account · Contact · Case | D23: Fax | E23: Account Fax | F23: Phone | G23: 40 | T23: Standard | V23: Org describe (DCCA sandbox)
A24: Account | B24: Account | C24: Core: Account · Contact · Case | D24: FirstName | E24: First Name | F24: Text | G24: 40 | T24: Standard | V24: Org describe (DCCA sandbox)
A25: Account | B25: Account | C25: Core: Account · Contact · Case | D25: Id | E25: Account ID | F25: Id | G25: 18 | T25: Standard | V25: Org describe (DCCA sandbox)
A26: Account | B26: Account | C26: Core: Account · Contact · Case | D26: Industry | E26: Industry | F26: Picklist | G26: 255 | N26: Agriculture; Apparel; Banking; Biotechnology; Chemicals; Communications; Construction; Consulting; Education; Electronics; Energy; Engineering; Entertainment; Environmental; Finance; Food & Beverage; Government; Healthcare; Hospitality; Insurance; Machinery; Manufacturing; Media; Not For Profit; Other; Recreation; Retail; Shipping; Technology; Telecommunications; Transportation; Utilities | T26: Standard | V26: Org describe (DCCA sandbox)
A27: Account | B27: Account | C27: Core: Account · Contact · Case | D27: IsCustomerPortal | E27: Customer Portal Account | F27: Checkbox | T27: Standard | V27: Org describe (DCCA sandbox)
A28: Account | B28: Account | C28: Core: Account · Contact · Case | D28: IsDeleted | E28: Deleted | F28: Checkbox | T28: Standard | V28: Org describe (DCCA sandbox)
A29: Account | B29: Account | C29: Core: Account · Contact · Case | D29: IsPersonAccount | E29: Is Person Account | F29: Checkbox | T29: Standard | V29: Org describe (DCCA sandbox)
A30: Account | B30: Account | C30: Core: Account · Contact · Case | D30: IsPriorityRecord | E30: Important | F30: Checkbox | T30: Standard | V30: Org describe (DCCA sandbox)
A31: Account | B31: Account | C31: Core: Account · Contact · Case | D31: Jigsaw | E31: Data.com Key | F31: Text | G31: 20 | T31: Standard | V31: Org describe (DCCA sandbox)
A32: Account | B32: Account | C32: Core: Account · Contact · Case | D32: JigsawCompanyId | E32: Jigsaw Company ID | F32: Text | G32: 20 | L32: JigsawCompany | T32: Standard | V32: Org describe (DCCA sandbox)
A33: Account | B33: Account | C33: Core: Account · Contact · Case | D33: LastActivityDate | E33: Last Activity | F33: Date | T33: Standard | V33: Org describe (DCCA sandbox)
A34: Account | B34: Account | C34: Core: Account · Contact · Case | D34: LastModifiedById | E34: Last Modified By ID | F34: Lookup | G34: 18 | K34: User | L34: LastModifiedBy | M34: Lookup | T34: Standard | V34: Org describe (DCCA sandbox)
A35: Account | B35: Account | C35: Core: Account · Contact · Case | D35: LastModifiedDate | E35: Last Modified Date | F35: DateTime | T35: Standard | V35: Org describe (DCCA sandbox)
A36: Account | B36: Account | C36: Core: Account · Contact · Case | D36: LastName | E36: Last Name | F36: Text | G36: 80 | T36: Standard | V36: Org describe (DCCA sandbox)
A37: Account | B37: Account | C37: Core: Account · Contact · Case | D37: LastReferencedDate | E37: Last Referenced Date | F37: DateTime | T37: Standard | V37: Org describe (DCCA sandbox)
A38: Account | B38: Account | C38: Core: Account · Contact · Case | D38: LastViewedDate | E38: Last Viewed Date | F38: DateTime | T38: Standard | V38: Org describe (DCCA sandbox)
A39: Account | B39: Account | C39: Core: Account · Contact · Case | D39: MasterRecordId | E39: Master Record ID | F39: Lookup | G39: 18 | K39: Account | L39: MasterRecord | M39: Lookup | T39: Standard | V39: Org describe (DCCA sandbox)
A40: Account | B40: Account | C40: Core: Account · Contact · Case | D40: MiddleName | E40: Middle Name | F40: Text | G40: 40 | T40: Standard | V40: Org describe (DCCA sandbox)
A41: Account | B41: Account | C41: Core: Account · Contact · Case | D41: Name | E41: Account Name | F41: Text | G41: 255 | T41: Standard | V41: Org describe (DCCA sandbox)
...

Sheet Relationships
A1: Relationships
A2: Every lookup / master-detail / hierarchy field. Domains are looked up live from the Object Catalogue.
A3: ‹ Back to README
A5: Child Object | B5: Child Domain | C5: Field API Name | D5: Field Label | E5: Relationship Type | F5: Parent Object | G5: Parent Domain | H5: Child Relationship Name | I5: Required | J5: Crosses Domain | K5: Shown in ERD | L5: Source
A6: Account | B6: =IFERROR(INDEX('Object Catalogue'!$D:$D,MATCH(A6,'Object Catalogue'!$A:$A,0)),"Platform / managed") | C6: Contact__c | D6: Paying Contact | E6: Lookup | F6: Contact | G6: =IFERROR(INDEX('Object Catalogue'!$D:$D,MATCH(F6,'Object Catalogue'!$A:$A,0)),"Platform / managed") | H6: Contact__r | J6: =IF(B6=G6,"No","Yes") | K6: Yes | L6: Org describe (DCCA sandbox)
A7: Account | B7: =IFERROR(INDEX('Object Catalogue'!$D:$D,MATCH(A7,'Object Catalogue'!$A:$A,0)),"Platform / managed") | C7: MasterRecordId | D7: Master Record ID | E7: Lookup | F7: Account | G7: =IFERROR(INDEX('Object Catalogue'!$D:$D,MATCH(F7,'Object Catalogue'!$A:$A,0)),"Platform / managed") | H7: MasterRecord | J7: =IF(B7=G7,"No","Yes") | K7: Yes | L7: Org describe (DCCA sandbox)
A8: Account | B8: =IFERROR(INDEX('Object Catalogue'!$D:$D,MATCH(A8,'Object Catalogue'!$A:$A,0)),"Platform / managed") | C8: OwnerId | D8: Owner ID | E8: Lookup | F8: User | G8: =IFERROR(INDEX('Object Catalogue'!$D:$D,MATCH(F8,'Object Catalogue'!$A:$A,0)),"Platform / managed") | H8: Owner | J8: =IF(B8=G8,"No","Yes") | K8: No (User/system lookup) | L8: Org describe (DCCA sandbox)
A9: Account | B9: =IFERROR(INDEX('Object Catalogue'!$D:$D,MATCH(A9,'Object Catalogue'!$A:$A,0)),"Platform / managed") | C9: ParentId | D9: Parent Account ID | E9: Lookup | F9: Account | G9: =IFERROR(INDEX('Object Catalogue'!$D:$D,MATCH(F9,'Object Catalogue'!$A:$A,0)),"Platform / managed") | H9: Parent | J9: =IF(B9=G9,"No","Yes") | K9: Yes | L9: Org describe (DCCA sandbox)
A10: Account | B10: =IFERROR(INDEX('Object Catalogue'!$D:$D,MATCH(A10,'Object Catalogue'!$A:$A,0)),"Platform / managed") | C10: PersonContactId | D10: Contact ID | E10: Lookup | F10: Contact | G10: =IFERROR(INDEX('Object Catalogue'!$D:$D,MATCH(F10,'Object Catalogue'!$A:$A,0)),"Platform / managed") | H10: PersonContact | J10: =IF(B10=G10,"No","Yes") | K10: Yes | L10: Org describe (DCCA sandbox)
A11: Account | B11: =IFERROR(INDEX('Object Catalogue'!$D:$D,MATCH(A11,'Object Catalogue'!$A:$A,0)),"Platform / managed") | C11: PersonIndividualId | D11: Individual ID | E11: Lookup | F11: Individual | G11: =IFERROR(INDEX('Object Catalogue'!$D:$D,MATCH(F11,'Object Catalogue'!$A:$A,0)),"Platform / managed") | H11: PersonIndividual | J11: =IF(B11=G11,"No","Yes") | K11: Yes | L11: Org describe (DCCA sandbox)
A12: Account | B12: =IFERROR(INDEX('Object Catalogue'!$D:$D,MATCH(A12,'Object Catalogue'!$A:$A,0)),"Platform / managed") | C12: PersonReportsToId | D12: Reports To ID | E12: Lookup | F12: Contact | G12: =IFERROR(INDEX('Object Catalogue'!$D:$D,MATCH(F12,'Object Catalogue'!$A:$A,0)),"Platform / managed") | H12: PersonReportsTo | J12: =IF(B12=G12,"No","Yes") | K12: Yes | L12: Org describe (DCCA sandbox)
A13: Account | B13: =IFERROR(INDEX('Object Catalogue'!$D:$D,MATCH(A13,'Object Catalogue'!$A:$A,0)),"Platform / managed") | C13: RecordTypeId | D13: Record Type ID | E13: Lookup | F13: RecordType | G13: =IFERROR(INDEX('Object Catalogue'!$D:$D,MATCH(F13,'Object Catalogue'!$A:$A,0)),"Platform / managed") | H13: RecordType | J13: =IF(B13=G13,"No","Yes") | K13: No (User/system lookup) | L13: Org describe (DCCA sandbox)
A14: Account | B14: =IFERROR(INDEX('Object Catalogue'!$D:$D,MATCH(A14,'Object Catalogue'!$A:$A,0)),"Platform / managed") | C14: breg_Account_Affiliation__pc | D14: Account Affiliation | E14: Lookup | F14: breg_Account_Affiliation__c | G14: =IFERROR(INDEX('Object Catalogue'!$D:$D,MATCH(F14,'Object Catalogue'!$A:$A,0)),"Platform / managed") | H14: breg_Account_Affiliation__pr | J14: =IF(B14=G14,"No","Yes") | K14: Yes | L14: Org describe (DCCA sandbox)
A15: Account | B15: =IFERROR(INDEX('Object Catalogue'!$D:$D,MATCH(A15,'Object Catalogue'!$A:$A,0)),"Platform / managed") | C15: breg_Certified_Register_Agent__c | D15: Current Active Agent | E15: Lookup | F15: breg_Account_Affiliation__c | G15: =IFERROR(INDEX('Object Catalogue'!$D:$D,MATCH(F15,'Object Catalogue'!$A:$A,0)),"Platform / managed") | H15: breg_Certified_Register_Agent__r | J15: =IF(B15=G15,"No","Yes") | K15: Yes | L15: Org describe (DCCA sandbox)
A16: Account | B16: =IFERROR(INDEX('Object Catalogue'!$D:$D,MATCH(A16,'Object Catalogue'!$A:$A,0)),"Platform / managed") | C16: breg_Creator__c | D16: Creator | E16: Lookup | F16: User | G16: =IFERROR(INDEX('Object Catalogue'!$D:$D,MATCH(F16,'Object Catalogue'!$A:$A,0)),"Platform / managed") | H16: breg_Creator__r | J16: =IF(B16=G16,"No","Yes") | K16: No (User/system lookup) | L16: Org describe (DCCA sandbox)
A17: Account | B17: =IFERROR(INDEX('Object Catalogue'!$D:$D,MATCH(A17,'Object Catalogue'!$A:$A,0)),"Platform / managed") | C17: breg_Pending_Transaction__c | D17: Pending Transaction | E17: Lookup | F17: breg_Transaction__c | G17: =IFERROR(INDEX('Object Catalogue'!$D:$D,MATCH(F17,'Object Catalogue'!$A:$A,0)),"Platform / managed") | H17: breg_Pending_Transaction__r | J17: =IF(B17=G17,"No","Yes") | K17: Yes | L17: Org describe (DCCA sandbox)
... A26: AdditionalDependentAppsLicenses__c | B26: =IFERROR(INDEX('Object Catalogue'!$D:$D,MATCH(A26,'Object Catalogue'!$A:$A,0)),"Platform / managed") | C26: DependentLicense__c | D26: Dependent License | E26: Lookup | F26: License__c | G26: =IFERROR(INDEX('Object Catalogue'!$D:$D,MATCH(F26,'Object Catalogue'!$A:$A,0)),"Platform / managed") | H26: AdditionalDependentAppsLicenses | J26: =IF(B26=G26,"No","Yes") | K26: Yes | L26: Source metadata
A27: AllegationViolation__c | B27: =IFERROR(INDEX('Object Catalogue'!$D:$D,MATCH(A27,'Object Catalogue'!$A:$A,0)),"Platform / managed") | C27: Allegation__c | D27: Allegation | E27: Master-detail | F27: Allegation__c | G27: =IFERROR(INDEX('Object Catalogue'!$D:$D,MATCH(F27,'Object Catalogue'!$A:$A,0)),"Platform / managed") | H27: AllegationViolation | I27: Yes | J27: =IF(B27=G27,"No","Yes") | K27: Yes | L27: Source metadata
A28: AllegationViolation__c | B28: =IFERROR(INDEX('Object Catalogue'!$D:$D,MATCH(A28,'Object Catalogue'!$A:$A,0)),"Platform / managed") | C28: Violation__c | D28: Violation | E28: Master-detail | F28: Violation__c | G28: =IFERROR(INDEX('Object Catalogue'!$D:$D,MATCH(F28,'Object Catalogue'!$A:$A,0)),"Platform / managed") | H28: AllegationViolation | I28: Yes | J28: =IF(B28=G28,"No","Yes") | K28: Yes | L28: Source metadata
A29: Allegation__c | B29: =IFERROR(INDEX('Object Catalogue'!$D:$D,MATCH(A29,'Object Catalogue'!$A:$A,0)),"Platform / managed") | C29: SEBCaseContact__c | D29: SEB Case Contact | E29: Lookup | F29: SEBCaseContact__c | G29: =IFERROR(INDEX('Object Catalogue'!$D:$D,MATCH(F29,'Object Catalogue'!$A:$A,0)),"Platform / managed") | H29: Allegations | J29: =IF(B29=G29,"No","Yes") | K29: Yes | L29: Source metadata
A30: Allegation__c | B30: =IFERROR(INDEX('Object Catalogue'!$D:$D,MATCH(A30,'Object Catalogue'!$A:$A,0)),"Platform / managed") | C30: SEBCaseID__c | D30: SEB Case ID | E30: Master-detail | F30: SEBCase__c | G30: =IFERROR(INDEX('Object Catalogue'!$D:$D,MATCH(F30,'Object Catalogue'!$A:$A,0)),"Platform / managed") | H30: Allegations | I30: Yes | J30: =IF(B30=G30,"No","Yes") | K30: Yes | L30: Source metadata
A31: ApplicationClassifications__c | B31: =IFERROR(INDEX('Object Catalogue'!$D:$D,MATCH(A31,'Object Catalogue'!$A:$A,0)),"Platform / managed") | C31: Application__c | D31: Application | E31: Master-detail | F31: Application__c | G31: =IFERROR(INDEX('Object Catalogue'!$D:$D,MATCH(F31,'Object Catalogue'!$A:$A,0)),"Platform / managed") | H31: Application_Classifications | I31: Yes | J31: =IF(B31=G31,"No","Yes") | K31: Yes | L31: Source metadata
A32: ApplicationClassifications__c | B32: =IFERROR(INDEX('Object Catalogue'!$D:$D,MATCH(A32,'Object Catalogue'!$A:$A,0)),"Platform / managed") | C32: Classification__c | D32: Classification | E32: Master-detail | F32: Classification__c | G32: =IFERROR(INDEX('Object Catalogue'!$D:$D,MATCH(F32,'Object Catalogue'!$A:$A,0)),"Platform / managed") | H32: Application_Classifications | I32: Yes | J32: =IF(B32=G32,"No","Yes") | K32: Yes | L32: Source metadata
A33: ApplicationClassifications__c | B33: =IFERROR(INDEX('Object Catalogue'!$D:$D,MATCH(A33,'Object Catalogue'!$A:$A,0)),"Platform / managed") | C33: LicenseType__c | D33: License Type | E33: Lookup | F33: LicenseType__c | G33: =IFERROR(INDEX('Object Catalogue'!$D:$D,MATCH(F33,'Object Catalogue'!$A:$A,0)),"Platform / managed") | H33: Application_Classifications | J33: =IF(B33=G33,"No","Yes") | K33: Yes | L33: Source metadata
A34: ApplicationRequirement__c | B34: =IFERROR(INDEX('Object Catalogue'!$D:$D,MATCH(A34,'Object Catalogue'!$A:$A,0)),"Platform / managed") | C34: Application__c | D34: Application | E34: Master-detail | F34: Application__c | G34: =IFERROR(INDEX('Object Catalogue'!$D:$D,MATCH(F34,'Object Catalogue'!$A:$A,0)),"Platform / managed") | H34: Application_Deficiencies | I34: Yes | J34: =IF(B34=G34,"No","Yes") | K34: Yes | L34: Source metadata
A35: ApplicationRequirement__c | B35: =IFERROR(INDEX('Object Catalogue'!$D:$D,MATCH(A35,'Object Catalogue'!$A:$A,0)),"Platform / managed") | C35: ParentApplicationRequirement__c | D35: Parent Application Requirement | E35: Lookup | F35: ApplicationRequirement__c | G35: =IFERROR(INDEX('Object Catalogue'!$D:$D,MATCH(F35,'Object Catalogue'!$A:$A,0)),"Platform / managed") | H35: ApplicationRequirements | J35: =IF(B35=G35,"No","Yes") | K35: Yes | L35: Source metadata
A36: ApplicationRequirement__c | B36: =IFERROR(INDEX('Object Catalogue'!$D:$D,MATCH(A36,'Object Catalogue'!$A:$A,0)),"Platform / managed") | C36: Requirement__c | D36: Requirement | E36: Lookup | F36: Requirements__c | G36: =IFERROR(INDEX('Object Catalogue'!$D:$D,MATCH(F36,'Object Catalogue'!$A:$A,0)),"Platform / managed") | H36: Application_Requirements | J36: =IF(B36=G36,"No","Yes") | K36: Yes | L36: Source metadata
A37: Application_Cache__c | B37: =IFERROR(INDEX('Object Catalogue'!$D:$D,MATCH(A37,'Object Catalogue'!$A:$A,0)),"Platform / managed") | C37: Application_Meta_Data__c | D37: Application Meta Data | E37: Lookup | F37: Application_Meta_Data__c | G37: =IFERROR(INDEX('Object Catalogue'!$D:$D,MATCH(F37,'Object Catalogue'!$A:$A,0)),"Platform / managed") | H37: Application_Cache | J37: =IF(B37=G37,"No","Yes") | K37: Yes | L37: Source metadata
A38: Application_Cache__c | B38: =IFERROR(INDEX('Object Catalogue'!$D:$D,MATCH(A38,'Object Catalogue'!$A:$A,0)),"Platform / managed") | C38: Duties_Reassessment_Application__c | D38: Reassessment Application | E38: Lookup | F38: Application__c | G38: =IFERROR(INDEX('Object Catalogue'!$D:$D,MATCH(F38,'Object Catalogue'!$A:$A,0)),"Platform / managed") | H38: Draft_Applications | J38: =IF(B38=G38,"No","Yes") | K38: Yes | L38: Source metadata
A39: Application_Cache__c | B39: =IFERROR(INDEX('Object Catalogue'!$D:$D,MATCH(A39,'Object Catalogue'!$A:$A,0)),"Platform / managed") | C39: PVLPortalUser__c | D39: PVL Portal User | E39: Lookup | F39: PVL_Portal_User__c | G39: =IFERROR(INDEX('Object Catalogue'!$D:$D,MATCH(F39,'Object Catalogue'!$A:$A,0)),"Platform / managed") | H39: Draft_Applications | J39: =IF(B39=G39,"No","Yes") | K39: Yes | L39: Source metadata
A40: Application_Cache__c | B40: =IFERROR(INDEX('Object Catalogue'!$D:$D,MATCH(A40,'Object Catalogue'!$A:$A,0)),"Platform / managed") | C40: Previous_Owner__c | D40: Previous Owner | E40: Lookup | F40: User | G40: =IFERROR(INDEX('Object Catalogue'!$D:$D,MATCH(F40,'Object Catalogue'!$A:$A,0)),"Platform / managed") | H40: PreviousOwnerDraftApplications | J40: =IF(B40=G40,"No","Yes") | K40: No (User/system lookup) | L40: Source metadata
A41: Application__c | B41: =IFERROR(INDEX('Object Catalogue'!$D:$D,MATCH(A41,'Object Catalogue'!$A:$A,0)),"Platform / managed") | C41: Applicant__c | D41: Applicant | E41: Lookup | F41: Account | G41: =IFERROR(INDEX('Object Catalogue'!$D:$D,MATCH(F41,'Object Catalogue'!$A:$A,0)),"Platform / managed") | H41: Applications | J41: =IF(B41=G41,"No","Yes") | K41: Yes | L41: Source metadata
A42: Application__c | B42: =IFERROR(INDEX('Object Catalogue'!$D:$D,MATCH(A42,'Object Catalogue'!$A:$A,0)),"Platform / managed") | C42: Consultant__c | D42: Consultant | E42: Lookup | F42: Account | G42: =IFERROR(INDEX('Object Catalogue'!$D:$D,MATCH(F42,'Object Catalogue'!$A:$A,0)),"Platform / managed") | H42: Applications2 | J42: =IF(B42=G42,"No","Yes") | K42: Yes | L42: Source metadata
A43: Application__c | B43: =IFERROR(INDEX('Object Catalogue'!$D:$D,MATCH(A43,'Object Catalogue'!$A:$A,0)),"Platform / managed") | C43: CurrentLicense__c | D43: Current License | E43: Lookup | F43: License__c | G43: =IFERROR(INDEX('Object Catalogue'!$D:$D,MATCH(F43,'Object Catalogue'!$A:$A,0)),"Platform / managed") | H43: Applications1 | J43: =IF(B43=G43,"No","Yes") | K43: Yes | L43: Source metadata
A44: Application__c | B44: =IFERROR(INDEX('Object Catalogue'!$D:$D,MATCH(A44,'Object Catalogue'!$A:$A,0)),"Platform / managed") | C44: DependentApplication__c | D44: Dependent Application | E44: Lookup | F44: Application__c | G44: =IFERROR(INDEX('Object Catalogue'!$D:$D,MATCH(F44,'Object Catalogue'!$A:$A,0)),"Platform / managed") | H44: Dependent_Applications | J44: =IF(B44=G44,"No","Yes") | K44: Yes | L44: Source metadata
A45: Application__c | B45: =IFERROR(INDEX('Object Catalogue'!$D:$D,MATCH(A45,'Object Catalogue'!$A:$A,0)),"Platform / managed") | C45: DependentLicense2__c | D45: Dependent License 2 | E45: Lookup | F45: License__c | G45: =IFERROR(INDEX('Object Catalogue'!$D:$D,MATCH(F45,'Object Catalogue'!$A:$A,0)),"Platform / managed") | H45: Applications2 | J45: =IF(B45=G45,"No","Yes") | K45: Yes | L45: Source metadata
A46: Application__c | B46: =IFERROR(INDEX('Object Catalogue'!$D:$D,MATCH(A46,'Object Catalogue'!$A:$A,0)),"Platform / managed") | C46: DependentLicense__c | D46: Dependent License | E46: Lookup | F46: License__c | G46: =IFERROR(INDEX('Object Catalogue'!$D:$D,MATCH(F46,'Object Catalogue'!$A:$A,0)),"Platform / managed") | H46: Applications | J46: =IF(B46=G46,"No","Yes") | K46: Yes | L46: Source metadata
... A51: AssociatedLicense__c | B51: =IFERROR(INDEX('Object Catalogue'!$D:$D,MATCH(A51,'Object Catalogue'!$A:$A,0)),"Platform / managed") | C51: EmployeeLicense__c | D51: Employee License | E51: Lookup | F51: License__c | G51: =IFERROR(INDEX('Object Catalogue'!$D:$D,MATCH(F51,'Object Catalogue'!$A:$A,0)),"Platform / managed") | H51: AssociatedEntities | J51: =IF(B51=G51,"No","Yes") | K51: Yes | L51: Source metadata
A52: AssociatedLicense__c | B52: =IFERROR(INDEX('Object Catalogue'!$D:$D,MATCH(A52,'Object Catalogue'!$A:$A,0)),"Platform / managed") | C52: EntityLicense__c | D52: Entity License | E52: Master-detail | F52: License__c | G52: =IFERROR(INDEX('Object Catalogue'!$D:$D,MATCH(F52,'Object Catalogue'!$A:$A,0)),"Platform / managed") | H52: AssociatedEmployee | I52: Yes | J52: =IF(B52=G52,"No","Yes") | K52: Yes | L52: Source metadata
A53: Associated_Account__c | B53: =IFERROR(INDEX('Object Catalogue'!$D:$D,MATCH(A53,'Object Catalogue'!$A:$A,0)),"Platform / managed") | C53: Account__c | D53: Account | E53: Lookup | F53: Account | G53: =IFERROR(INDEX('Object Catalogue'!$D:$D,MATCH(F53,'Object Catalogue'!$A:$A,0)),"Platform / managed") | H53: Associated_Accounts | J53: =IF(B53=G53,"No","Yes") | K53: Yes | L53: Source metadata
...

Sheet Core Object References
A1: Account, Contact & Case: Inbound References
A2: Every object that looks up to Account, Contact or Case, and the lookups those three objects hold.
A3: ‹ Back to README
A5: Core Object | B5: Direction | C5: Related Object | D5: Related Object Domain | E5: Field API Name | F5: Field Label | G5: Relationship Type
A6: Account | B6: Inbound (child → core) | C6: breg_Account_Affiliation__c | D6: BREG: Business Registration | E6: breg_Account__c | F6: Account | G6: Lookup
A7: Account | B7: Inbound (child → core) | C7: breg_Account_Affiliation__c | D7: BREG: Business Registration | E7: breg_Entity__c | F7: Entity | G7: Lookup
A8: Account | B8: Inbound (child → core) | C8: breg_Acquisition_Transaction__c | D8: BREG: Business Registration | E8: breg_Merged_Entity__c | F8: Merged Entity | G8: Lookup
A9: Account | B9: Inbound (child → core) | C9: breg_Annual__c | D9: BREG: Business Registration | E9: breg_Account__c | F9: Account | G9: Lookup
A10: Account | B10: Inbound (child → core) | C10: breg_Certificate__c | D10: BREG: Business Registration | E10: breg_Account__c | F10: Account | G10: Lookup
A11: Account | B11: Inbound (child → core) | C11: breg_Document__c | D11: BREG: Business Registration | E11: breg_Account__c | F11: Account | G11: Lookup
A12: Account | B12: Inbound (child → core) | C12: breg_Log__c | D12: BREG: Business Registration | E12: breg_Account__c | F12: Account | G12: Lookup
A13: Account | B13: Inbound (child → core) | C13: breg_Notification__c | D13: BREG: Business Registration | E13: breg_Account__c | F13: Account | G13: Lookup
A14: Account | B14: Inbound (child → core) | C14: breg_Stock__c | D14: BREG: Business Registration | E14: breg_Account__c | F14: Account | G14: Lookup
A15: Account | B15: Inbound (child → core) | C15: breg_TN_TM_SM__c | D15: BREG: Business Registration | E15: breg_Account__c | F15: Account | G15: Lookup
A16: Account | B16: Inbound (child → core) | C16: breg_Test_Annual__c | D16: BREG: Business Registration | E16: breg_Account__c | F16: Account | G16: Lookup
... A137: Contact | B137: Outbound (core → parent) | C137: breg_Transaction__c | D137: BREG: Business Registration | E137: breg_Transaction__c | F137: Transaction | G137: Lookup

Sheet Record Types
A1: Record Types
A2: 343 record types across all objects.
A3: ‹ Back to README
A5: Object API Name | B5: Domain | C5: Record Type API Name | D5: Record Type Label | E5: Active | F5: Description | G5: Source
A6: Account | B6: Core: Account · Contact · Case | C6: BREG_Account | D6: BREG Account | E6: Yes | G6: Org describe (DCCA sandbox)
A7: Account | B7: Core: Account · Contact · Case | C7: BREG_Member_Account | D7: BREG Member Account | E7: Yes | G7: Org describe (DCCA sandbox)
A8: Account | B8: Core: Account · Contact · Case | C8: BusinessAccount | D8: Business Account | E8: Yes | G8: Org describe (DCCA sandbox)
A9: Account | B9: Core: Account · Contact · Case | C9: PVL | D9: Call Center | E9: Yes | G9: Org describe (DCCA sandbox)
A10: Account | B10: Core: Account · Contact · Case | C10: Complainant | D10: Complainant | E10: Yes | G10: Org describe (DCCA sandbox)
A11: Account | B11: Core: Account · Contact · Case | C11: DCCA_CATV | D11: DCCA CATV | E11: Yes | G11: Org describe (DCCA sandbox)
A12: Account | B12: Core: Account · Contact · Case | C12: PVLAttendee | D12: PVL - Attendee | E12: Yes | G12: Org describe (DCCA sandbox)
